2023-02-12 02:22:22 [ERROR] - 构造数据异常
2023-02-12 02:22:22 [ERROR] - Traceback (most recent call last):
  File "/opt/hostedtoolcache/Python/3.8.16/x64/lib/python3.8/site-packages/urllib3/connection.py", line 159, in _new_conn
    conn = connection.create_connection(
  File "/opt/hostedtoolcache/Python/3.8.16/x64/lib/python3.8/site-packages/urllib3/util/connection.py", line 61, in create_connection
    for res in socket.getaddrinfo(host, port, family, socket.SOCK_STREAM):
  File "/opt/hostedtoolcache/Python/3.8.16/x64/lib/python3.8/socket.py", line 918, in getaddrinfo
    for res in _socket.getaddrinfo(host, port, family, type, proto, flags):
socket.gaierror: [Errno -5] No address associated with hostname

During handling of the above exception, another exception occurred:

Traceback (most recent call last):
  File "/opt/hostedtoolcache/Python/3.8.16/x64/lib/python3.8/site-packages/urllib3/connectionpool.py", line 670, in urlopen
    httplib_response = self._make_request(
  File "/opt/hostedtoolcache/Python/3.8.16/x64/lib/python3.8/site-packages/urllib3/connectionpool.py", line 381, in _make_request
    self._validate_conn(conn)
  File "/opt/hostedtoolcache/Python/3.8.16/x64/lib/python3.8/site-packages/urllib3/connectionpool.py", line 978, in _validate_conn
    conn.connect()
  File "/opt/hostedtoolcache/Python/3.8.16/x64/lib/python3.8/site-packages/urllib3/connection.py", line 309, in connect
    conn = self._new_conn()
  File "/opt/hostedtoolcache/Python/3.8.16/x64/lib/python3.8/site-packages/urllib3/connection.py", line 171, in _new_conn
    raise NewConnectionError(
urllib3.exceptions.NewConnectionError: <urllib3.connection.HTTPSConnection object at 0x7f8a415df190>: Failed to establish a new connection: [Errno -5] No address associated with hostname

During handling of the above exception, another exception occurred:

Traceback (most recent call last):
  File "/opt/hostedtoolcache/Python/3.8.16/x64/lib/python3.8/site-packages/requests/adapters.py", line 439, in send
    resp = conn.urlopen(
  File "/opt/hostedtoolcache/Python/3.8.16/x64/lib/python3.8/site-packages/urllib3/connectionpool.py", line 726, in urlopen
    retries = retries.increment(
  File "/opt/hostedtoolcache/Python/3.8.16/x64/lib/python3.8/site-packages/urllib3/util/retry.py", line 446, in increment
    raise MaxRetryError(_pool, url, error or ResponseError(cause))
urllib3.exceptions.MaxRetryError: HTTPSConnectionPool(host='exp-blog.com', port=443): Max retries exceeded with url: /atom.xml (Caused by NewConnectionError('<urllib3.connection.HTTPSConnection object at 0x7f8a415df190>: Failed to establish a new connection: [Errno -5] No address associated with hostname'))

During handling of the above exception, another exception occurred:

Traceback (most recent call last):
  File "main.py", line 84, in main
    data_ar = article.build(github_token, proxy)
  File "/home/runner/work/lyy289065406/lyy289065406/src/builder/article.py", line 32, in build
    rows.extend(ar.get_tops(MODE_RSS, settings.app['article_num']))
  File "/home/runner/work/lyy289065406/lyy289065406/src/builder/article.py", line 82, in get_tops
    articles = self._get_top_articles(mode, top)
  File "/home/runner/work/lyy289065406/lyy289065406/src/builder/article.py", line 117, in _get_top_articles
    rsp = requests.get(
  File "/opt/hostedtoolcache/Python/3.8.16/x64/lib/python3.8/site-packages/requests/api.py", line 75, in get
    return request('get', url, params=params, **kwargs)
  File "/opt/hostedtoolcache/Python/3.8.16/x64/lib/python3.8/site-packages/requests/api.py", line 60, in request
    return session.request(method=method, url=url, **kwargs)
  File "/opt/hostedtoolcache/Python/3.8.16/x64/lib/python3.8/site-packages/requests/sessions.py", line 533, in request
    resp = self.send(prep, **send_kwargs)
  File "/opt/hostedtoolcache/Python/3.8.16/x64/lib/python3.8/site-packages/requests/sessions.py", line 646, in send
    r = adapter.send(request, **kwargs)
  File "/opt/hostedtoolcache/Python/3.8.16/x64/lib/python3.8/site-packages/requests/adapters.py", line 516, in send
    raise ConnectionError(e, request=request)
requests.exceptions.ConnectionError: HTTPSConnectionPool(host='exp-blog.com', port=443): Max retries exceeded with url: /atom.xml (Caused by NewConnectionError('<urllib3.connection.HTTPSConnection object at 0x7f8a415df190>: Failed to establish a new connection: [Errno -5] No address associated with hostname'))

2023-04-20 02:02:54 [ERROR] - 构造数据异常
2023-04-20 02:02:54 [ERROR] - Traceback (most recent call last):
  File "main.py", line 84, in main
    data_ar = article.build(github_token, proxy)
  File "/home/runner/work/lyy289065406/lyy289065406/src/builder/article.py", line 42, in build
    rows.extend(ar.get_tops(MODE_SITEMAP, 1))
  File "/home/runner/work/lyy289065406/lyy289065406/src/builder/article.py", line 88, in get_tops
    articles = self._get_top_articles(mode, top)
  File "/home/runner/work/lyy289065406/lyy289065406/src/builder/article.py", line 118, in _get_top_articles
    time = self._query_filetime(url)
  File "/home/runner/work/lyy289065406/lyy289065406/src/builder/article.py", line 150, in _query_filetime
    return _git.query_filetime(self.gtk, self.repo_name, filepath)
  File "/home/runner/work/lyy289065406/lyy289065406/src/utils/_git.py", line 97, in query_filetime
    filetime = fileinfo[0]["commit"]["committedDate"]
IndexError: list index out of range

2023-04-21 02:04:22 [ERROR] - 构造数据异常
2023-04-21 02:04:22 [ERROR] - Traceback (most recent call last):
  File "main.py", line 84, in main
    data_ar = article.build(github_token, proxy)
  File "/home/runner/work/lyy289065406/lyy289065406/src/builder/article.py", line 42, in build
    rows.extend(ar.get_tops(MODE_SITEMAP, 1))
  File "/home/runner/work/lyy289065406/lyy289065406/src/builder/article.py", line 88, in get_tops
    articles = self._get_top_articles(mode, top)
  File "/home/runner/work/lyy289065406/lyy289065406/src/builder/article.py", line 118, in _get_top_articles
    time = self._query_filetime(url)
  File "/home/runner/work/lyy289065406/lyy289065406/src/builder/article.py", line 150, in _query_filetime
    return _git.query_filetime(self.gtk, self.repo_name, filepath)
  File "/home/runner/work/lyy289065406/lyy289065406/src/utils/_git.py", line 97, in query_filetime
    filetime = fileinfo[0]["commit"]["committedDate"]
IndexError: list index out of range

2023-04-22 02:04:58 [ERROR] - 构造数据异常
2023-04-22 02:04:58 [ERROR] - Traceback (most recent call last):
  File "main.py", line 84, in main
    data_ar = article.build(github_token, proxy)
  File "/home/runner/work/lyy289065406/lyy289065406/src/builder/article.py", line 42, in build
    rows.extend(ar.get_tops(MODE_SITEMAP, 1))
  File "/home/runner/work/lyy289065406/lyy289065406/src/builder/article.py", line 88, in get_tops
    articles = self._get_top_articles(mode, top)
  File "/home/runner/work/lyy289065406/lyy289065406/src/builder/article.py", line 118, in _get_top_articles
    time = self._query_filetime(url)
  File "/home/runner/work/lyy289065406/lyy289065406/src/builder/article.py", line 150, in _query_filetime
    return _git.query_filetime(self.gtk, self.repo_name, filepath)
  File "/home/runner/work/lyy289065406/lyy289065406/src/utils/_git.py", line 97, in query_filetime
    filetime = fileinfo[0]["commit"]["committedDate"]
IndexError: list index out of range

